<?xml version="1.0" ?>
<robot name="au_bot" xmlns:xacro="http://www.ros.org/wiki/xacro">

<xacro:arg name="use_ros2_control" default="true"/>
<xacro:arg name="sim_mode" default="false"/>

<xacro:include filename="$(find au_bot_description)/urdf/materials.xacro" />
<xacro:if value="$(arg use_ros2_control)">
  <xacro:include filename="$(find au_bot_description)/urdf/au_bot.ros2control" />
</xacro:if>
<xacro:unless value="$(arg use_ros2_control)">
  <xacro:include filename="gz_control.xacro" />
</xacro:unless>
<xacro:include filename="$(find au_bot_description)/urdf/sensor_plugin.xacro" />
<xacro:include filename="$(find au_bot_description)/urdf/au_bot.trans" />
<xacro:include filename="$(find au_bot_description)/urdf/au_bot.gazebo" />

<!-- BASE_FOOTPRINT LINK -->
  <joint name="base_footprint_joint" type="fixed">
    <parent link="base_footprint"/>
    <child link="base_link"/>
    <origin xyz="0 0 0.001" rpy="0 0 0"/>
  </joint>

  <link name="base_footprint">
  </link>
  
<link name="base_link">
  <inertial>
    <origin xyz="-0.011877227491278293 -0.0002133943635731113 0.053609847274168704" rpy="0 0 0"/>
    <mass value="0.590294967554169"/>
    <inertia ixx="0.000797" iyy="0.001526" izz="0.001446" ixy="-1.1e-05" iyz="1e-06" ixz="-1.6e-05"/>
  </inertial>
  <visual>
    <origin xyz="0 0 0" rpy="0 0 0"/>
    <geometry>
      <mesh filename="file://$(find au_bot_description)/meshes/base_link.stl" scale="0.001 0.001 0.001"/>
    </geometry>
    <material name="orange"/>
  </visual>
  <collision>
    <origin xyz="0 0 0" rpy="0 0 0"/>
    <geometry>
      <mesh filename="file://$(find au_bot_description)/meshes/base_link.stl" scale="0.001 0.001 0.001"/>
    </geometry>
  </collision>
</link>

<link name="left_wheel_1">
  <inertial>
    <origin xyz="2.981497979753778e-08 -0.0033716027582890024 1.4051532121195365e-05" rpy="0 0 0"/>
    <mass value="0.004154170291999658"/>
    <inertia ixx="2e-06" iyy="2e-06" izz="4e-06" ixy="0.0" iyz="-0.0" ixz="0.0"/>
  </inertial>
  <visual>
    <origin xyz="-0.05 -0.0665 -0.017015" rpy="0 0 0"/>
    <geometry>
      <mesh filename="file://$(find au_bot_description)/meshes/left_wheel_1.stl" scale="0.001 0.001 0.001"/>
    </geometry>
    <material name="black"/>
  </visual>
  <collision>
    <origin xyz="-0.05 -0.0665 -0.017015" rpy="0 0 0"/>
    <geometry>
      <mesh filename="file://$(find au_bot_description)/meshes/left_wheel_1.stl" scale="0.001 0.001 0.001"/>
    </geometry>
  </collision>
</link>

<link name="right_wheel_1">
  <inertial>
    <origin xyz="2.981497973508773e-08 0.0033716027582889885 -1.4520496034741565e-05" rpy="0 0 0"/>
    <mass value="0.004154170291999658"/>
    <inertia ixx="2e-06" iyy="2e-06" izz="4e-06" ixy="0.0" iyz="0.0" ixz="-0.0"/>
  </inertial>
  <visual>
    <origin xyz="-0.05 0.0665 -0.017015" rpy="0 0 0"/>
    <geometry>
      <mesh filename="file://$(find au_bot_description)/meshes/right_wheel_1.stl" scale="0.001 0.001 0.001"/>
    </geometry>
    <material name="black"/>
  </visual>
  <collision>
    <origin xyz="-0.05 0.0665 -0.017015" rpy="0 0 0"/>
    <geometry>
      <mesh filename="file://$(find au_bot_description)/meshes/right_wheel_1.stl" scale="0.001 0.001 0.001"/>
    </geometry>
  </collision>
</link>

<link name="caster_1">
  <inertial>
    <origin xyz="-1.0824674490095276e-15 -4.7311564979596e-18 -0.006239717155397626" rpy="0 0 0"/>
    <mass value="0.020274803712154146"/>
    <inertia ixx="2e-06" iyy="1e-06" izz="2e-06" ixy="-0.0" iyz="0.0" ixz="0.0"/>
  </inertial>
  <visual>
    <origin xyz="0.044 -0.0 -0.019" rpy="0 0 0"/>
    <geometry>
      <mesh filename="file://$(find au_bot_description)/meshes/caster_1.stl" scale="0.001 0.001 0.001"/>
    </geometry>
    <material name="silver"/>
  </visual>
  <collision>
    <origin xyz="0.044 -0.0 -0.019" rpy="0 0 0"/>
    <geometry>
      <mesh filename="file://$(find au_bot_description)/meshes/caster_1.stl" scale="0.001 0.001 0.001"/>
    </geometry>
  </collision>
</link>

<link name="lidar_1">
  <inertial>
    <origin xyz="-7.867109045523596e-05 -0.0061511440736577785 0.011400548145502593" rpy="0 0 0"/>
    <mass value="0.014024092646244959"/>
    <inertia ixx="4e-06" iyy="4e-06" izz="5e-06" ixy="0.0" iyz="0.0" ixz="-0.0"/>
  </inertial>
  <visual>
    <origin xyz="-0.054225 -0.028626 -0.0975" rpy="0 0 0"/>
    <geometry>
      <mesh filename="file://$(find au_bot_description)/meshes/lidar_1.stl" scale="0.001 0.001 0.001"/>
    </geometry>
    <material name="blue"/>
  </visual>
  <collision>
    <origin xyz="-0.054225 -0.028626 -0.0975" rpy="0 0 0"/>
    <geometry>
      <mesh filename="file://$(find au_bot_description)/meshes/lidar_1.stl" scale="0.001 0.001 0.001"/>
    </geometry>
  </collision>
</link>

<joint name="lftw" type="continuous">
  <origin xyz="0.05 0.0665 0.017015" rpy="0 0 0"/>
  <parent link="base_link"/>
  <child link="left_wheel_1"/>
  <axis xyz="0.0 1.0 0.0"/>
</joint>

<joint name="rgtw" type="continuous">
  <origin xyz="0.05 -0.0665 0.017015" rpy="0 0 0"/>
  <parent link="base_link"/>
  <child link="right_wheel_1"/>
  <axis xyz="0.0 1.0 0.0"/>
</joint>

<joint name="cstr" type="fixed">
  <origin xyz="-0.044 0.0 0.019" rpy="0 0 0"/>
  <parent link="base_link"/>
  <child link="caster_1"/>
</joint>

<joint name="ldr" type="fixed">
  <origin xyz="0.054225 0.028626 0.0975" rpy="0 0 0"/>
  <parent link="base_link"/>
  <child link="lidar_1"/>
</joint>

</robot>
